Сравниваем значения: 822b53b2-3e53-9a3e-8d9c-d410bf8c43a5 и (.venv) ivanvoronov@MacBook-Air-Ivan pom_uitesting_playground % pytest -v --alluredir=./allure-results ========================================================================= test session starts ========================================================================= platform darwin -- Python 3.10.7, pytest-8.3.4, pluggy-1.5.0 -- /Users/ivanvoronov/PycharmProjects/pom_uitesting_playground/.venv/bin/python cachedir: .pytest_cache rootdir: /Users/ivanvoronov/PycharmProjects/pom_uitesting_playground configfile: pytest.ini plugins: allure-pytest-2.13.5, rerunfailures-15.0, xdist-3.6.1 4 workers [5 items]      scheduling tests via LoadScheduling  tests/test_features_ui_playground.py::TestFeaturesUiPlayground::test_ajax_data  tests/test_features_ui_playground.py::TestFeaturesUiPlayground::test_client_side_delay_page  tests/test_features_ui_playground.py::TestFeaturesUiPlayground::test_mouse_page  tests/test_features_ui_playground.py::TestFeaturesUiPlayground::test_progress_bar  INTERNALERROR> def worker_internal_error( INTERNALERROR>         self, node: WorkerController, formatted_error: str INTERNALERROR>     ) -> None: INTERNALERROR>         """ INTERNALERROR>         pytest_internalerror() was called on the worker. INTERNALERROR>      INTERNALERROR>         pytest_internalerror() arguments are an excinfo and an excrepr, which can't INTERNALERROR>         be serialized, so we go with a poor man's solution of raising an exception INTERNALERROR>         here ourselves using the formatted message. INTERNALERROR>         """ INTERNALERROR>         self._active_nodes.remove(node) INTERNALERROR>         try: INTERNALERROR> >           assert False, formatted_error INTERNALERROR> E           AssertionError: Traceback (most recent call last): INTERNALERROR> E               File "/Users/ivanvoronov/PycharmProjects/pom_uitesting_playground/.venv/lib/python3.10/site-packages/_pytest/main.py", line 283, in wrap_session INTERNALERROR> E                 session.exitstatus = doit(config, session) or 0 INTERNALERROR> E               File "/Users/ivanvoronov/PycharmProjects/pom_uitesting_playground/.venv/lib/python3.10/site-packages/_pytest/main.py", line 337, in _main INTERNALERROR> E                 config.hook.pytest_runtestloop(session=session) INTERNALERROR> E               File "/Users/ivanvoronov/PycharmProjects/pom_uitesting_playground/.venv/lib/python3.10/site-packages/pluggy/_hooks.py", line 513, in __call__ INTERNALERROR> E                 return self._hookexec(self.name, self._hookimpls.copy(), kwargs, firstresult) INTERNALERROR> E               File "/Users/ivanvoronov/PycharmProjects/pom_uitesting_playground/.venv/lib/python3.10/site-packages/pluggy/_manager.py", line 120, in _hookexec INTERNALERROR> E                 return self._inner_hookexec(hook_name, methods, kwargs, firstresult) INTERNALERROR> E               File "/Users/ivanvoronov/PycharmProjects/pom_uitesting_playground/.venv/lib/python3.10/site-packages/pluggy/_callers.py", line 139, in _multicall INTERNALERROR> E                 raise exception.with_traceback(exception.__traceback__) INTERNALERROR> E               File "/Users/ivanvoronov/PycharmProjects/pom_uitesting_playground/.venv/lib/python3.10/site-packages/pluggy/_callers.py", line 122, in _multicall INTERNALERROR> E                 teardown.throw(exception)  # type: ignore[union-attr] INTERNALERROR> E               File "/Users/ivanvoronov/PycharmProjects/pom_uitesting_playground/.venv/lib/python3.10/site-packages/_pytest/logging.py", line 803, in pytest_runtestloop INTERNALERROR> E                 return (yield)  # Run all the tests. INTERNALERROR> E               File "/Users/ivanvoronov/PycharmProjects/pom_uitesting_playground/.venv/lib/python3.10/site-packages/pluggy/_callers.py", line 122, in _multicall INTERNALERROR> E                 teardown.throw(exception)  # type: ignore[union-attr] INTERNALERROR> E               File "/Users/ivanvoronov/PycharmProjects/pom_uitesting_playground/.venv/lib/python3.10/site-packages/_pytest/terminal.py", line 673, in pytest_runtestloop INTERNALERROR> E                 result = yield INTERNALERROR> E               File "/Users/ivanvoronov/PycharmProjects/pom_uitesting_playground/.venv/lib/python3.10/site-packages/pluggy/_callers.py", line 103, in _multicall INTERNALERROR> E                 res = hook_impl.function(*args) INTERNALERROR> E               File "/Users/ivanvoronov/PycharmProjects/pom_uitesting_playground/.venv/lib/python3.10/site-packages/xdist/remote.py", line 174, in pytest_runtestloop INTERNALERROR> E                 self.run_one_test() INTERNALERROR> E               File "/Users/ivanvoronov/PycharmProjects/pom_uitesting_playground/.venv/lib/python3.10/site-packages/xdist/remote.py", line 195, in run_one_test INTERNALERROR> E                 self.config.hook.pytest_runtest_protocol(item=item, nextitem=nextitem) INTERNALERROR> E               File "/Users/ivanvoronov/PycharmProjects/pom_uitesting_playground/.venv/lib/python3.10/site-packages/pluggy/_hooks.py", line 513, in __call__ INTERNALERROR> E                 return self._hookexec(self.name, self._hookimpls.copy(), kwargs, firstresult) INTERNALERROR> E               File "/Users/ivanvoronov/PycharmProjects/pom_uitesting_playground/.venv/lib/python3.10/site-packages/pluggy/_manager.py", line 120, in _hookexec INTERNALERROR> E                 return self._inner_hookexec(hook_name, methods, kwargs, firstresult) INTERNALERROR> E               File "/Users/ivanvoronov/PycharmProjects/pom_uitesting_playground/.venv/lib/python3.10/site-packages/pluggy/_callers.py", line 182, in _multicall INTERNALERROR> E                 return outcome.get_result() INTERNALERROR> E               File "/Users/ivanvoronov/PycharmProjects/pom_uitesting_playground/.venv/lib/python3.10/site-packages/pluggy/_result.py", line 100, in get_result INTERNALERROR> E                 raise exc.with_traceback(exc.__traceback__) INTERNALERROR> E               File "/Users/ivanvoronov/PycharmProjects/pom_uitesting_playground/.venv/lib/python3.10/site-packages/pluggy/_callers.py", line 167, in _multicall INTERNALERROR> E                 teardown.throw(outcome._exception) INTERNALERROR> E               File "/Users/ivanvoronov/PycharmProjects/pom_uitesting_playground/.venv/lib/python3.10/site-packages/_pytest/warnings.py", line 112, in pytest_runtest_protocol INTERNALERROR> E                 return (yield) INTERNALERROR> E               File "/Users/ivanvoronov/PycharmProjects/pom_uitesting_playground/.venv/lib/python3.10/site-packages/pluggy/_callers.py", line 167, in _multicall INTERNALERROR> E                 teardown.throw(outcome._exception) INTERNALERROR> E               File "/Users/ivanvoronov/PycharmProjects/pom_uitesting_playground/.venv/lib/python3.10/site-packages/_pytest/assertion/__init__.py", line 176, in pytest_runtest_protocol INTERNALERROR> E                 return (yield) INTERNALERROR> E               File "/Users/ivanvoronov/PycharmProjects/pom_uitesting_playground/.venv/lib/python3.10/site-packages/pluggy/_callers.py", line 167, in _multicall INTERNALERROR> E                 teardown.throw(outcome._exception) INTERNALERROR> E               File "/Users/ivanvoronov/PycharmProjects/pom_uitesting_playground/.venv/lib/python3.10/site-packages/_pytest/unittest.py", line 429, in pytest_runtest_protocol INTERNALERROR> E                 res = yield INTERNALERROR> E               File "/Users/ivanvoronov/PycharmProjects/pom_uitesting_playground/.venv/lib/python3.10/site-packages/pluggy/_callers.py", line 167, in _multicall INTERNALERROR> E                 teardown.throw(outcome._exception) INTERNALERROR> E               File "/Users/ivanvoronov/PycharmProjects/pom_uitesting_playground/.venv/lib/python3.10/site-packages/_pytest/faulthandler.py", line 88, in pytest_runtest_protocol INTERNALERROR> E                 return (yield) INTERNALERROR> E               File "/Users/ivanvoronov/PycharmProjects/pom_uitesting_playground/.venv/lib/python3.10/site-packages/pluggy/_callers.py", line 103, in _multicall INTERNALERROR> E                 res = hook_impl.function(*args) INTERNALERROR> E               File "/Users/ivanvoronov/PycharmProjects/pom_uitesting_playground/.venv/lib/python3.10/site-packages/pytest_rerunfailures.py", line 566, in pytest_runtest_protocol INTERNALERROR> E                 reports = runtestprotocol(item, nextitem=nextitem, log=False) INTERNALERROR> E               File "/Users/ivanvoronov/PycharmProjects/pom_uitesting_playground/.venv/lib/python3.10/site-packages/_pytest/runner.py", line 126, in runtestprotocol INTERNALERROR> E                 rep = call_and_report(item, "setup", log) INTERNALERROR> E               File "/Users/ivanvoronov/PycharmProjects/pom_uitesting_playground/.venv/lib/python3.10/site-packages/_pytest/runner.py", line 248, in call_and_report INTERNALERROR> E                 ihook.pytest_exception_interact(node=item, call=call, report=report) INTERNALERROR> E               File "/Users/ivanvoronov/PycharmProjects/pom_uitesting_playground/.venv/lib/python3.10/site-packages/pluggy/_hooks.py", line 513, in __call__ INTERNALERROR> E                 return self._hookexec(self.name, self._hookimpls.copy(), kwargs, firstresult) INTERNALERROR> E               File "/Users/ivanvoronov/PycharmProjects/pom_uitesting_playground/.venv/lib/python3.10/site-packages/pluggy/_manager.py", line 120, in _hookexec INTERNALERROR> E                 return self._inner_hookexec(hook_name, methods, kwargs, firstresult) INTERNALERROR> E               File "/Users/ivanvoronov/PycharmProjects/pom_uitesting_playground/.venv/lib/python3.10/site-packages/pluggy/_callers.py", line 139, in _multicall INTERNALERROR> E                 raise exception.with_traceback(exception.__traceback__) INTERNALERROR> E               File "/Users/ivanvoronov/PycharmProjects/pom_uitesting_playground/.venv/lib/python3.10/site-packages/pluggy/_callers.py", line 103, in _multicall INTERNALERROR> E                 res = hook_impl.function(*args) INTERNALERROR> E               File "/Users/ivanvoronov/PycharmProjects/pom_uitesting_playground/conftest.py", line 54, in pytest_exception_interact INTERNALERROR> E                 driver = node.instance.driver INTERNALERROR> E             AttributeError: 'TestFeaturesUiPlayground' object has no attribute 'driver' INTERNALERROR> E           assert False INTERNALERROR>  INTERNALERROR> .venv/lib/python3.10/site-packages/xdist/dsession.py:232: AssertionError INTERNALERROR> Traceback (most recent call last): INTERNALERROR>   File "/Users/ivanvoronov/PycharmProjects/pom_uitesting_playground/.venv/lib/python3.10/site-packages/_pytest/main.py", line 283, in wrap_session INTERNALERROR>     session.exitstatus = doit(config, session) or 0 INTERNALERROR>   File "/Users/ivanvoronov/PycharmProjects/pom_uitesting_playground/.venv/lib/python3.10/site-packages/_pytest/main.py", line 337, in _main INTERNALERROR>     config.hook.pytest_runtestloop(session=session) INTERNALERROR>   File "/Users/ivanvoronov/PycharmProjects/pom_uitesting_playground/.venv/lib/python3.10/site-packages/pluggy/_hooks.py", line 513, in __call__ INTERNALERROR>     return self._hookexec(self.name, self._hookimpls.copy(), kwargs, firstresult) INTERNALERROR>   File "/Users/ivanvoronov/PycharmProjects/pom_uitesting_playground/.venv/lib/python3.10/site-packages/pluggy/_manager.py", line 120, in _hookexec INTERNALERROR>     return self._inner_hookexec(hook_name, methods, kwargs, firstresult) INTERNALERROR>   File "/Users/ivanvoronov/PycharmProjects/pom_uitesting_playground/.venv/lib/python3.10/site-packages/pluggy/_callers.py", line 139, in _multicall INTERNALERROR>     raise exception.with_traceback(exception.__traceback__) INTERNALERROR>   File "/Users/ivanvoronov/PycharmProjects/pom_uitesting_playground/.venv/lib/python3.10/site-packages/pluggy/_callers.py", line 122, in _multicall INTERNALERROR>     teardown.throw(exception)  # type: ignore[union-attr] INTERNALERROR>   File "/Users/ivanvoronov/PycharmProjects/pom_uitesting_playground/.venv/lib/python3.10/site-packages/_pytest/logging.py", line 803, in pytest_runtestloop INTERNALERROR>     return (yield)  # Run all the tests. INTERNALERROR>   File "/Users/ivanvoronov/PycharmProjects/pom_uitesting_playground/.venv/lib/python3.10/site-packages/pluggy/_callers.py", line 122, in _multicall INTERNALERROR>     teardown.throw(exception)  # type: ignore[union-attr] INTERNALERROR>   File "/Users/ivanvoronov/PycharmProjects/pom_uitesting_playground/.venv/lib/python3.10/site-packages/_pytest/terminal.py", line 673, in pytest_runtestloop INTERNALERROR>     result = yield INTERNALERROR>   File "/Users/ivanvoronov/PycharmProjects/pom_uitesting_playground/.venv/lib/python3.10/site-packages/pluggy/_callers.py", line 103, in _multicall INTERNALERROR>     res = hook_impl.function(*args) INTERNALERROR>   File "/Users/ivanvoronov/PycharmProjects/pom_uitesting_playground/.venv/lib/python3.10/site-packages/xdist/dsession.py", line 138, in pytest_runtestloop INTERNALERROR>     self.loop_once() INTERNALERROR>   File "/Users/ivanvoronov/PycharmProjects/pom_uitesting_playground/.venv/lib/python3.10/site-packages/xdist/dsession.py", line 163, in loop_once INTERNALERROR>     call(**kwargs) INTERNALERROR>   File "/Users/ivanvoronov/PycharmProjects/pom_uitesting_playground/.venv/lib/python3.10/site-packages/xdist/dsession.py", line 217, in worker_workerfinished INTERNALERROR>     assert not crashitem, (crashitem, node) INTERNALERROR> AssertionError: ('tests/test_features_ui_playground.py::TestFeaturesUiPlayground::test_client_side_delay_page', <WorkerController gw0>) INTERNALERROR> assert not 'tests/test_features_ui_playground.py::TestFeaturesUiPlayground::test_client_side_delay_page'  ========================================================================= 5 warnings in 0.49s ========================================================================= (.venv) ivanvoronov@MacBook-Air-Ivan pom_uitesting_playground % 
